Workbook

Sheet Planilha3
A3: Contagem de CHAVE | B3: Rótulos de Coluna
A4: Pedidos parados na base | B4: 590 | C4: 1030 | D4: 1100 | E4: (vazio) | F4: Total Geral
A5: EM PROCESSO DE DEVOLUÇÃO | D5: 1 | F5: 1
A6: ENTREGA PROGRAMADA | D6: 1 | F6: 1
A7: PENDENCIA | B7: 5 | D7: 24 | F7: 29
A8: PROXIMA ROTA | C8: 1 | D8: 3 | F8: 4
A9: PROXIMA ROTA - INTERIOR | B9: 5 | D9: 13 | F9: 18
A10: (vazio)
A11: Total Geral | B11: 10 | C11: 1 | D11: 42 | F11: 53

Sheet Plan1
A1: NF | B1: CHAVE | C1: OCORRENCIA | D1: CD/FILIAL | E1: DATA ENTRADA | F1: PEDIDO
A2: 837506 | B2: 52261047960950110733550070008375061054708359 | C2: ENTREGA PROGRAMADA | D2: =VLOOKUP(A2,Planilha1!B:E,4,0) -> 1100 | E2: =VLOOKUP(A2,Planilha1!B:G,6,0) -> 46316 | F2: =INDEX(Planilha1!A:A,MATCH(Plan1!A2,Planilha1!B:B,0)) -> 1187418754
A3: 831572 | B3: 52261047960950110733550070008315721032568030 | C3: PENDENCIA | D3: =VLOOKUP(A3,Planilha1!B:E,4,0) -> 1100 | E3: =VLOOKUP(A3,Planilha1!B:G,6,0) -> 46312 | F3: =INDEX(Planilha1!A:A,MATCH(Plan1!A3,Planilha1!B:B,0)) -> 1186126117
A4: 840313 | B4: 52261047960950110733550070008403131051529327 | C4: PENDENCIA | D4: =VLOOKUP(A4,Planilha1!B:E,4,0) -> 1100 | E4: =VLOOKUP(A4,Planilha1!B:G,6,0) -> 46317 | F4: =INDEX(Planilha1!A:A,MATCH(Plan1!A4,Planilha1!B:B,0)) -> 1187751980
A5: 836159 | B5: 52261047960950110733550070008361591059140358 | C5: PENDENCIA | D5: =VLOOKUP(A5,Planilha1!B:E,4,0) -> 1100 | E5: =VLOOKUP(A5,Planilha1!B:G,6,0) -> 46315 | F5: =INDEX(Planilha1!A:A,MATCH(Plan1!A5,Planilha1!B:B,0)) -> 1187255273
A6: 835315 | B6: 52261047960950110733550070008353151020388539 | C6: PENDENCIA | D6: =VLOOKUP(A6,Planilha1!B:E,4,0) -> 1100 | E6: =VLOOKUP(A6,Planilha1!B:G,6,0) -> 46315 | F6: =INDEX(Planilha1!A:A,MATCH(Plan1!A6,Planilha1!B:B,0)) -> 1187183753
A7: 829361 | B7: 52261047960950110733550070008293611051270405 | C7: PENDENCIA | D7: =VLOOKUP(A7,Planilha1!B:E,4,0) -> 1100 | E7: =VLOOKUP(A7,Planilha1!B:G,6,0) -> 46311 | F7: =INDEX(Planilha1!A:A,MATCH(Plan1!A7,Planilha1!B:B,0)) -> 1186322301
A8: 832311 | B8: 52261047960950110733550070008323111029284725 | C8: PENDENCIA | D8: =VLOOKUP(A8,Planilha1!B:E,4,0) -> 1100 | E8: =VLOOKUP(A8,Planilha1!B:G,6,0) -> 46312 | F8: =INDEX(Planilha1!A:A,MATCH(Plan1!A8,Planilha1!B:B,0)) -> 1186823175
A9: 799509 | B9: 52260947960950110733550070007995091052703546 | C9: PENDENCIA | D9: =VLOOKUP(A9,Planilha1!B:E,4,0) -> 1100 | E9: =VLOOKUP(A9,Planilha1!B:G,6,0) -> 46294 | F9: =INDEX(Planilha1!A:A,MATCH(Plan1!A9,Planilha1!B:B,0)) -> 1182675812
A10: 836205 | B10: 52261047960950110733550070008362051043826586 | C10: PENDENCIA | D10: =VLOOKUP(A10,Planilha1!B:E,4,0) -> 1100 | E10: =VLOOKUP(A10,Planilha1!B:G,6,0) -> 46315 | F10: =INDEX(Planilha1!A:A,MATCH(Plan1!A10,Planilha1!B:B,0)) -> 1187296922
A11: 611384 | B11: 35261047960950089351550130006113841085856324 | C11: PENDENCIA | D11: =VLOOKUP(A11,Planilha1!B:E,4,0) -> 590 | E11: =VLOOKUP(A11,Planilha1!B:G,6,0) -> 46314 | F11: =INDEX(Planilha1!A:A,MATCH(Plan1!A11,Planilha1!B:B,0)) -> 1186169530
A12: 41320 | B12: 41261047960950177056550060000413201046671469 | C12: PENDENCIA | D12: =VLOOKUP(A12,Planilha1!B:E,4,0) -> 590 | E12: =VLOOKUP(A12,Planilha1!B:G,6,0) -> 46314 | F12: =INDEX(Planilha1!A:A,MATCH(Plan1!A12,Planilha1!B:B,0)) -> 1183934679
A13: 597663 | B13: 35261047960950089351550130005976631014116174 | C13: PENDENCIA | D13: =VLOOKUP(A13,Planilha1!B:E,4,0) -> 590 | E13: =VLOOKUP(A13,Planilha1!B:G,6,0) -> 46311 | F13: =INDEX(Planilha1!A:A,MATCH(Plan1!A13,Planilha1!B:B,0)) -> 1185876269
... A24: 756927 | B24: 52260947960950110733550070007569271058934894 | C24: PENDENCIA | D24: =VLOOKUP(A24,Planilha1!B:E,4,0) -> 1100 | E24: =VLOOKUP(A24,Planilha1!B:G,6,0) -> 46272 | F24: =INDEX(Planilha1!A:A,MATCH(Plan1!A24,Planilha1!B:B,0)) -> 1176016588
A25: 726472 | B25: 52260847960950110733550070007264721082890943 | C25: PENDENCIA | D25: 1100 | E25: =VLOOKUP(A25,Planilha1!B:G,6,0) -> #N/A | F25: =INDEX(Planilha1!A:A,MATCH(Plan1!A25,Planilha1!B:B,0)) -> #N/A
A26: 259893 | B26: 35260400349443000435551000002598931177583463 | C26: PENDENCIA | D26: 1100 | E26: =VLOOKUP(A26,Planilha1!B:G,6,0) -> #N/A | F26: =INDEX(Planilha1!A:A,MATCH(Plan1!A26,Planilha1!B:B,0)) -> #N/A
A27: 796404 | B27: 52260947960950110733550070007964041029614308 | C27: PENDENCIA | D27: =VLOOKUP(A27,Planilha1!B:E,4,0) -> 1100 | E27: =VLOOKUP(A27,Planilha1!B:G,6,0) -> 46293 | F27: =INDEX(Planilha1!A:A,MATCH(Plan1!A27,Planilha1!B:B,0)) -> 1182354986
A28: 738223 | B28: 52260847960950110733550070007382231041286682 | C28: PENDENCIA | D28: 1100 | E28: =VLOOKUP(A28,Planilha1!B:G,6,0) -> #N/A | F28: =INDEX(Planilha1!A:A,MATCH(Plan1!A28,Planilha1!B:B,0)) -> #N/A
A29: 813252 | B29: 52261047960950110733550070008132521011904122 | C29: PENDENCIA | D29: =VLOOKUP(A29,Planilha1!B:E,4,0) -> 1100 | E29: =VLOOKUP(A29,Planilha1!B:G,6,0) -> 46302 | F29: =INDEX(Planilha1!A:A,MATCH(Plan1!A29,Planilha1!B:B,0)) -> 1184612532
A30: 813252 | B30: 52261047960950110733550070008132521011904122 | C30: PENDENCIA | D30: =VLOOKUP(A30,Planilha1!B:E,4,0) -> 1100 | E30: =VLOOKUP(A30,Planilha1!B:G,6,0) -> 46302 | F30: =INDEX(Planilha1!A:A,MATCH(Plan1!A30,Planilha1!B:B,0)) -> 1184612532
A31: 807998 | B31: 52261047960950110733550070008079981089562256 | C31: PENDENCIA | D31: =VLOOKUP(A31,Planilha1!B:E,4,0) -> 1100 | E31: =VLOOKUP(A31,Planilha1!B:G,6,0) -> 46300 | F31: =INDEX(Planilha1!A:A,MATCH(Plan1!A31,Planilha1!B:B,0)) -> 1184041064
A32: 819680 | B32: 52261047960950110733550070008196801036220140 | C32: EM PROCESSO DE DEVOLUÇÃO | D32: =VLOOKUP(A32,Planilha1!B:E,4,0) -> 1100 | E32: =VLOOKUP(A32,Planilha1!B:G,6,0) -> 46305 | F32: =INDEX(Planilha1!A:A,MATCH(Plan1!A32,Planilha1!B:B,0)) -> 1185322066
A33: 816752 | B33: 52261047960950110733550070008167521029596358 | C33: PROXIMA ROTA - INTERIOR | D33: =VLOOKUP(A33,Planilha1!B:E,4,0) -> 1100 | E33: =VLOOKUP(A33,Planilha1!B:G,6,0) -> 46304 | F33: =INDEX(Planilha1!A:A,MATCH(Plan1!A33,Planilha1!B:B,0)) -> 1184121586
A34: 809305 | B34: 52261047960950110733550070008093051015708335 | C34: PROXIMA ROTA - INTERIOR | D34: =VLOOKUP(A34,Planilha1!B:E,4,0) -> 1100 | E34: =VLOOKUP(A34,Planilha1!B:G,6,0) -> 46300 | F34: =INDEX(Planilha1!A:A,MATCH(Plan1!A34,Planilha1!B:B,0)) -> 1184121945
A35: 840379 | B35: 52261047960950110733550070008403791031107429 | C35: PROXIMA ROTA - INTERIOR | D35: =VLOOKUP(A35,Planilha1!B:E,4,0) -> 1100 | E35: =VLOOKUP(A35,Planilha1!B:G,6,0) -> 46317 | F35: =INDEX(Planilha1!A:A,MATCH(Plan1!A35,Planilha1!B:B,0)) -> 1187748504
A36: 832337 | B36: 52261047960950110733550070008323371046024244 | C36: PROXIMA ROTA - INTERIOR | D36: =VLOOKUP(A36,Planilha1!B:E,4,0) -> 1100 | E36: =VLOOKUP(A36,Planilha1!B:G,6,0) -> 46312 | F36: =INDEX(Planilha1!A:A,MATCH(Plan1!A36,Planilha1!B:B,0)) -> 1186414964
A37: 2619 | B37: 35261041809726000157550030000026191464742541 | C37: PROXIMA ROTA - INTERIOR | D37: =VLOOKUP(A37,Planilha1!B:E,4,0) -> 590 | E37: =VLOOKUP(A37,Planilha1!B:G,6,0) -> 46268 | F37: =INDEX(Planilha1!A:A,MATCH(Plan1!A37,Planilha1!B:B,0)) -> 1565670102433049-1
A38: 836179 | B38: 52261047960950110733550070008361791019447056 | C38: PROXIMA ROTA - INTERIOR | D38: =VLOOKUP(A38,Planilha1!B:E,4,0) -> 1100 | E38: =VLOOKUP(A38,Planilha1!B:G,6,0) -> 46315 | F38: =INDEX(Planilha1!A:A,MATCH(Plan1!A38,Planilha1!B:B,0)) -> 1187252086
A39: 61450 | B39: 41261047960950177056550060000614501062802426 | C39: PROXIMA ROTA - INTERIOR | D39: =VLOOKUP(A39,Planilha1!B:E,4,0) -> 590 | E39: =VLOOKUP(A39,Planilha1!B:G,6,0) -> 46315 | F39: =INDEX(Planilha1!A:A,MATCH(Plan1!A39,Planilha1!B:B,0)) -> 1185697247
A40: 615752 | B40: 35261047960950089351550130006157521089155033 | C40: PROXIMA ROTA - INTERIOR | D40: =VLOOKUP(A40,Planilha1!B:E,4,0) -> 590 | E40: =VLOOKUP(A40,Planilha1!B:G,6,0) -> 46315 | F40: =INDEX(Planilha1!A:A,MATCH(Plan1!A40,Planilha1!B:B,0)) -> 1186568217
... A54: 48237 | B54: 52261047960950106620550010000482371053227098 | C54: PROXIMA ROTA | D54: =VLOOKUP(A54,Planilha1!B:E,4,0) -> 1030 | E54: =VLOOKUP(A54,Planilha1!B:G,6,0) -> 46317 | F54: =INDEX(Planilha1!A:A,MATCH(Plan1!A54,Planilha1!B:B,0)) -> 1187633471

Sheet Planilha1
A1: PEDIDO | B1: NF`s | C1: ROMANEIO/ID | D1: TRANSP / MOTO | E1: CD/FILIAL | F1: DATA_ROMANEIO | G1: DATA ENTRADA | H1: HORA | I1: PREVISÃO ENTREGA | J1: TIPO_FLUXO | K1: UUID-SISTEMA | L1: CHAVE | M1: OBS | N1: UUID-MOBILE | O1: Data_vencimento | P1: sem arquivo
A2: 1177057864 | B2: 748260 | C2: 118042718 | D2: 7834988 | E2: 1100 | F2: 46265 | G2: 46266 | H2: 0.041666667 | I2: 46266 | J2: Porta a Porta | L2: 52260847960950110733550070007482601014709427
A3: 1177106130 | B3: 748262 | C3: 118042718 | D3: 7834988 | E3: 1100 | F3: 46265 | G3: 46266 | H3: 0.041666667 | I3: 46266 | J3: Porta a Porta | L3: 52260847960950110733550070007482621067454738
A4: 1177102835 | B4: 748261 | C4: 118042718 | D4: 7834988 | E4: 1100 | F4: 46265 | G4: 46266 | H4: 0.041666667 | I4: 46266 | J4: Porta a Porta | L4: 52260847960950110733550070007482611066183687
A5: 1177085617 | B5: 748244 | C5: 118042718 | D5: 7834988 | E5: 1100 | F5: 46265 | G5: 46266 | H5: 0.041666667 | I5: 46266 | J5: Porta a Porta | L5: 52260847960950110733550070007482441023116987
A6: 1177067401 | B6: 748242 | C6: 118042718 | D6: 7834988 | E6: 1100 | F6: 46265 | G6: 46266 | H6: 0.041666667 | I6: 46266 | J6: Porta a Porta | L6: 52260847960950110733550070007482421023466878
A7: 1177070000 | B7: 748243 | C7: 118042718 | D7: 7834988 | E7: 1100 | F7: 46265 | G7: 46266 | H7: 0.041666667 | I7: 46266 | J7: Porta a Porta | L7: 52260847960950110733550070007482431037037122
A8: 1177039529 | B8: 748259 | C8: 118042718 | D8: 7834988 | E8: 1100 | F8: 46265 | G8: 46266 | H8: 0.041666667 | I8: 46266 | J8: Porta a Porta | L8: 52260847960950110733550070007482591038905870
A9: 1177092201 | B9: 748246 | C9: 118042718 | D9: 7834988 | E9: 1100 | F9: 46265 | G9: 46266 | H9: 0.041666667 | I9: 46266 | J9: Porta a Porta | L9: 52260847960950110733550070007482461076777117
A10: 1177057771 | B10: 748241 | C10: 118042718 | D10: 7834988 | E10: 1100 | F10: 46265 | G10: 46266 | H10: 0.041666667 | I10: 46266 | J10: Porta a Porta | L10: 52260847960950110733550070007482411082212561
A11: 1177086235 | B11: 748245 | C11: 118042718 | D11: 7834988 | E11: 1100 | F11: 46265 | G11: 46266 | H11: 0.041666667 | I11: 46266 | J11: Porta a Porta | L11: 52260847960950110733550070007482451074059821
A12: 1177157044 | B12: 748403 | C12: 118042718 | D12: 7834988 | E12: 1100 | F12: 46265 | G12: 46266 | H12: 0.041666667 | I12: 46266 | J12: Porta a Porta | L12: 52260847960950110733550070007484031081865243
A13: 1177152261 | B13: 748404 | C13: 118042718 | D13: 7834988 | E13: 1100 | F13: 46265 | G13: 46266 | H13: 0.041666667 | I13: 46266 | J13: Porta a Porta | L13: 52260847960950110733550070007484041020328873
... A137: 1177282797 | B137: 749086 | C137: 118044921 | D137: 7834995 | E137: 1100 | F137: 46266 | G137: 46266 | H137: 0.16666667 | I137: 46266 | J137: Porta a Porta | L137: 52260947960950110733550070007490861074559840
A138: 1177289386 | B138: 749087 | C138: 118044921 | D138: 7834995 | E138: 1100 | F138: 46266 | G138: 46266 | H138: 0.16666667 | I138: 46266 | J138: Porta a Porta | L138: 52260947960950110733550070007490871056293823 | M138: Carta de embalagem
A139: 1177271709 | B139: 749085 | C139: 118044921 | D139: 7834995 | E139: 1100 | F139: 46266 | G139: 46266 | H139: 0.16666667 | I139: 46266 | J139: Porta a Porta | L139: 52260947960950110733550070007490851013433955
A140: 1177193818 | B140: 749151 | C140: 118044922 | D140: 7834995 | E140: 1100 | F140: 46266 | G140: 46266 | H140: 0.16666667 | I140: 46266 | J140: Porta a Porta | L140: 52260947960950110733550070007491511089352040 | M140: Carta de embalagem
A141: 1177271449 | B141: 749169 | C141: 118044922 | D141: 7834995 | E141: 1100 | F141: 46266 | G141: 46266 | H141: 0.16666667 | I141: 46266 | J141: Porta a Porta | L141: 52260947960950110733550070007491691057457339
A142: 1177289819 | B142: 749170 | C142: 118044922 | D142: 7834995 | E142: 1100 | F142: 46266 | G142: 46266 | H142: 0.16666667 | I142: 46266 | J142: Porta a Porta | L142: 52260947960950110733550070007491701076430581
A143: 1177265357 | B143: 749176 | C143: 118044922 | D143: 7834995 | E143: 1100 | F143: 46266 | G143: 46266 | H143: 0.16666667 | I143: 46266 | J143: Porta a Porta | L143: 52260947960950110733550070007491761034811572
A144: 1177228248 | B144: 749209 | C144: 118044922 | D144: 7834995 | E144: 1100 | F144: 46266 | G144: 46266 | H144: 0.16666667 | I144: 46266 | J144: Porta a Porta | L144: 52260947960950110733550070007492091035412771
A145: 1177226743 | B145: 749224 | C145: 118044922 | D145: 7834995 | E145: 1100 | F145: 46266 | G145: 46266 | H145: 0.16666667 | I145: 46266 | J145: Porta a Porta | L145: 52260947960950110733550070007492241014974629
A146: 1177230504 | B146: 749225 | C146: 118044922 | D146: 7834995 | E146: 1100 | F146: 46266 | G146: 46266 | H146: 0.16666667 | I146: 46266 | J146: Porta a Porta | L146: 52260947960950110733550070007492251032409099
A147: 1177252453 | B147: 749174 | C147: 118044922 | D147: 7834995 | E147: 1100 | F147: 46266 | G147: 46266 | H147: 0.16666667 | I147: 46266 | J147: Porta a Porta | L147: 52260947960950110733550070007491741073670513
A148: 1177251547 | B148: 749238 | C148: 118044922 | D148: 7834995 | E148: 1100 | F148: 46266 | G148: 46266 | H148: 0.16666667 | I148: 46266 | J148: Porta a Porta | L148: 52260947960950110733550070007492381079388770
A149: 1177240017 | B149: 749201 | C149: 118044922 | D149: 7834995 | E149: 1100 | F149: 46266 | G149: 46266 | H149: 0.16666667 | I149: 46266 | J149: Porta a Porta | L149: 52260947960950110733550070007492011089152753
A150: 1177259376 | B150: 749244 | C150: 118044922 | D150: 7834995 | E150: 1100 | F150: 46266 | G150: 46266 | H150: 0.16666667 | I150: 46266 | J150: Porta a Porta | L150: 52260947960950110733550070007492441059750960
A151: 1177184026 | B151: 749241 | C151: 118044922 | D151: 7834995 | E151: 1100 | F151: 46266 | G151: 46266 | H151: 0.16666667 | I151: 46266 | J151: Porta a Porta | L151: 52260947960950110733550070007492411058043036
A152: 1177218490 | B152: 749242 | C152: 118044922 | D152: 7834995 | E152: 1100 | F152: 46266 | G152: 46266 | H152: 0.16666667 | I152: 46266 | J152: Porta a Porta | L152: 52260947960950110733550070007492421059040526
... A202: 1177221759 | B202: 749220 | C202: 118044922 | D202: 7834995 | E202: 1100 | F202: 46266 | G202: 46266 | H202: 0.16666667 | I202: 46266 | J202: Porta a Porta | L202: 52260947960950110733550070007492201045954868
A203: 1177235625 | B203: 749229 | C203: 118044922 | D203: 7834995 | E203: 1100 | F203: 46266 | G203: 46266 | H203: 0.16666667 | I203: 46266 | J203: Porta a Porta | L203: 52260947960950110733550070007492291014655333 | M203: Carta de embalagem
A204: 1177213397 | B204: 749200 | C204: 118044922 | D204: 7834995 | E204: 1100 | F204: 46266 | G204: 46266 | H204: 0.16666667 | I204: 46266 | J204: Porta a Porta | L204: 52260947960950110733550070007492001027778163
A205: 1177248449 | B205: 749199 | C205: 118044922 | D205: 7834995 | E205: 1100 | F205: 46266 | G205: 46266 | H205: 0.16666667 | I205: 46266 | J205: Porta a Porta | L205: 52260947960950110733550070007491991024223400
A206: 1177244357 | B206: 749234 | C206: 118044922 | D206: 7834995 | E206: 1100 | F206: 46266 | G206: 46266 | H206: 0.16666667 | I206: 46266 | J206: Porta a Porta | L206: 52260947960950110733550070007492341059594341
A207: 1177034101 | B207: 749110 | C207: 118044922 | D207: 7834995 | E207: 1100 | F207: 46266 | G207: 46266 | H207: 0.16666667 | I207: 46266 | J207: Porta a Porta | L207: 52260947960950110733550070007491101036461739
A208: 1177158760 | B208: 749098 | C208: 118044922 | D208: 7834995 | E208: 1100 | F208: 46266 | G208: 46266 | H208: 0.16666667 | I208: 46266 | J208: Porta a Porta | L208: 52260947960950110733550070007490981066151898
A209: 1177197465 | B209: 749109 | C209: 118044922 | D209: 7834995 | E209: 1100 | F209: 46266 | G209: 46266 | H209: 0.16666667 | I209: 46266 | J209: Porta a Porta | L209: 52260947960950110733550070007491091027729197
A210: 1177175872 | B210: 749133 | C210: 118044922 | D210: 7834995 | E210: 1100 | F210: 46266 | G210: 46266 | H210: 0.16666667 | I210: 46266 | J210: Porta a Porta | L210: 52260947960950110733550070007491331025147455
A211: 1177197543 | B211: 749105 | C211: 118044922 | D211: 7834995 | E211: 1100 | F211: 46266 | G211: 46266 | H211: 0.16666667 | I211: 46266 | J211: Porta a Porta | L211: 52260947960950110733550070007491051040296429
A212: 1177168415 | B212: 749101 | C212: 118044922 | D212: 7834995 | E212: 1100 | F212: 46266 | G212: 46266 | H212: 0.16666667 | I212: 46266 | J212: Porta a Porta | L212: 52260947960950110733550070007491011085474122
...
